<?xml version="1.0"?>
<robot xmlns:xacro="http://www.ros.org/wiki/xacro">

    <!-- BASE_FOOTPRINT -->
    <link name="base_footprint">
        <visual>
            <origin xyz="0 0 0" rpy="0 0 0" />
            <geometry>
                <box size="0.001 0.001 0.001" />
            </geometry>
        </visual>
    </link>

    <joint name="base_footprint_joint" type="fixed">
        <origin xyz="0 0 0.001" rpy="0 0 0" />
        <parent link="base_footprint"/>
        <child link="base_link" />
    </joint>

    <!-- BASE LINK -->
    <link name="base_link">
        <inertial>
            <origin xyz="-0.0224834781318358 0.043147185108824 0.15573045535703" rpy="0 0 0" />
            <mass value="9.12874381762573" />
            <inertia ixx="0.0703209223004399" ixy="0.000823792790695999" ixz="0.000375834309002579"
                     iyy="0.18869975254365" iyz="9.82268475527055E-07" izz="0.249106966997589" />
        </inertial>
        <visual>
            <origin xyz="0 0 0" rpy="0 0 0" />
            <geometry>
                <mesh filename="package://momo_description/meshes/visual/base_link.STL" />
            </geometry>
            <material name="">
                <color rgba="0.627450980392157 0.627450980392157 0.627450980392157 1" />
            </material>
        </visual>
        <collision>
            <origin xyz="0 0 0" rpy="0 0 0" />
            <geometry>
                <mesh filename="package://momo_description/meshes/visual/base_link.STL" />
            </geometry>
        </collision>
    </link>

    <!-- FRONT RIGHT WHEEL -->
    <link name="front_right_wheel">
        <inertial>
            <origin xyz="0.00235002849639554 0.00303838901454816 -0.0804375311167912" rpy="0 0 0" />
            <mass value="0.852354605102217" />
            <inertia ixx="0.000906831105798678" ixy="9.81283854227688E-07" ixz="2.23619743963333E-11"
                     iyy="0.000906168386374516" iyz="1.91429667110204E-11" izz="0.0010693441512525" />
        </inertial>
        <visual>
            <origin xyz="0 0 0" rpy="0 0 0" />
            <geometry>
                <mesh filename="package://momo_description/meshes/visual/front_right_wheel.STL" />
            </geometry>
            <material name="">
                <color rgba="0.792156862745098 0.819607843137255 0.933333333333333 1" />
            </material>
        </visual>
        <collision>
            <origin xyz="0 0 0" rpy="0 0 0" />
            <geometry>
                <mesh filename="package://momo_description/meshes/visual/front_right_wheel.STL" />
            </geometry>
        </collision>
    </link>
    <joint name="front_right_wheel_joint" type="continuous">
        <origin xyz="0.26849 -0.318 0.059996" rpy="1.5708 0 0" />
        <parent link="base_link" />
        <child link="front_right_wheel" />
        <axis xyz="0 0 -1" />
    </joint>

    <!-- BACK RIGHT WHEEL -->
    <link name="back_right_wheel">
        <inertial>
            <origin xyz="0.00235269913271367 0.00303881239038054 -0.0804375309775529" rpy="0 0 0" />
            <mass value="0.852354640622838" />
            <inertia ixx="0.000907345514266878" ixy="-5.98068915940485E-07" ixz="-2.00737014070952E-11"
                     iyy="0.000905654311384346" iyz="8.48507848540578E-12" izz="0.00106934438027434" />
        </inertial>
        <visual>
            <origin xyz="0 0 0" rpy="0 0 0" />
            <geometry>
                <mesh filename="package://momo_description/meshes/visual/back_right_wheel.STL" />
            </geometry>
            <material name="">
                <color rgba="0.792156862745098 0.819607843137255 0.933333333333333 1" />
            </material>
        </visual>
        <collision>
            <origin xyz="0 0 0" rpy="0 0 0" />
            <geometry>
                <mesh filename="package://momo_description/meshes/visual/back_right_wheel.STL" />
            </geometry>
        </collision>
    </link>
    <joint name="back_right_wheel_joint" type="continuous">
        <origin xyz="-0.27349334578749 -0.318000000000002 0.0599978846492716" rpy="1.5707963267949 0 0" />
        <parent link="base_link" />
        <child link="back_right_wheel" />
        <axis xyz="0 0 -1" />
    </joint>

    <!-- BACK LEFT WHEEL -->
    <link name="back_left_wheel">
        <inertial>
            <origin xyz="0.00235100431678491 0.00303777971566161 -0.00243588226510427" rpy="0 0 0" />
            <mass value="0.85235460510222" />
            <inertia ixx="0.000905522012701922" ixy="3.41693853969475E-07" ixz="-7.38335769311773E-12"
                     iyy="0.000907477479471278" iyz="-2.84955602367874E-11" izz="0.00106934415125251" />
        </inertial>
        <visual>
            <origin xyz="0 0 0" rpy="0 0 0" />
            <geometry>
                <mesh filename="package://momo_description/meshes/visual/back_left_wheel.STL" />
            </geometry>
            <material name="">
                <color rgba="0.792156862745098 0.819607843137255 0.933333333333333 1" />
            </material>
        </visual>
        <collision>
            <origin xyz="0 0 0" rpy="0 0 0" />
            <geometry>
                <mesh filename="package://momo_description/meshes/visual/back_left_wheel.STL" />
            </geometry>
        </collision>
    </link>
    <joint name="back_left_wheel_joint" type="continuous">
        <origin xyz="-0.273501168246142 0.318000000000003 0.0599931160727954" rpy="1.5707963267949 0 0" />
        <parent link="base_link" />
        <child link="back_left_wheel" />
        <axis xyz="0 0 -1" />
    </joint>

    <!-- FRONT LEFT WHEEL -->
    <link name="front_left_wheel">
        <inertial>
            <origin xyz="0.00234975130658399 0.00303912478874915 -0.00243588240434497" rpy="0 0 0" />
            <mass value="0.852354640622848" />
            <inertia ixx="0.000907516356656273" ixy="1.98922509533706E-07" ixz="-2.1406272773239E-11"
                     iyy="0.000905483468994953" iyz="-4.08920321728966E-12" izz="0.00106934438027433" />
        </inertial>
        <visual>
            <origin xyz="0 0 0" rpy="0 0 0" />
            <geometry>
                <mesh filename="package://momo_description/meshes/visual/front_left_wheel.STL" />
            </geometry>
            <material name="">
                <color rgba="0.792156862745098 0.819607843137255 0.933333333333333 1" />
            </material>
        </visual>
        <collision>
            <origin xyz="0 0 0" rpy="0 0 0" />
            <geometry>
                <mesh filename="package://momo_description/meshes/visual/front_left_wheel.STL" />
            </geometry>
        </collision>
    </link>
    <joint name="front_left_wheel_joint" type="continuous">
        <origin xyz="0.268493050220139 0.317999999999998 0.0599993263438537" rpy="1.5707963267949 0 0" />
        <parent link="base_link" />
        <child link="front_left_wheel" />
        <axis xyz="0 0 -1" />
    </joint>

</robot>
